Workbook

Sheet 안내
A1: 타닥타닥 우리반 · 한글 트랙 연습팩 검토표
A3: 이 표로 하는 일
A4: [전체 지문] 시트에서 각 지문을 읽고 [사용 여부] 칸에서 사용 / 빼기 / 고쳐서 사용 중 하나를 고르세요. 노란 칸만 선생님이 입력하는 칸이에요.
A5: 고쳐서 사용을 고르면 [선생님 메모] 칸에 바꿀 문장을 적어 주세요. 이 파일을 Claude에게 주면 JSON에 반영해요.
A7: 열 설명
A8: ID | B8: 플랫폼에서 쓰는 지문 번호 (ko-티어-단계-순번)
A9: 티어 / 단계 | B9: 티어 안에서 타수가 적은 지문부터 1→5단계로 나눔
A10: 목표 타수 / 정확도 | B10: 단계 통과 기준 (CLAUDE.md 3-2, 1번 넘으면 통과)
A11: 타수 | B11: 두벌식으로 실제 누르는 키 수. 겹모음·겹받침은 2타, 쌍자음은 Shift 포함 1타
A12: 예상 시간(초) | B12: 타수 ÷ 목표 타수 × 60. 목표 속도로 쳤을 때 걸리는 시간
A13: 단원 / 쪽 | B13: 교과서 출처 (브론즈는 자체 제작이라 비어 있음)
A14: 고친 점 | B14: 원문에서 바꾼 부분. 비어 있으면 교과서 문장 그대로
A15: 원문 일치율 | B15: 교과서 PDF와 글자를 대조한 비율. 1.00이면 교과서에 그대로 있음
A17: 예시 (실제 행과 같은 형식)
A18: ko-gold-1-01 · 골드 1단계 · 155타 · "문제는 해결해야 하는 일이나 과제를 말한다." · p.81 · 사용 여부: 사용

Sheet 요약
A1: 티어 | B1: 단계 | C1: 목표 타수 | D1: 지문 수 | E1: 평균 예상 시간(초) | F1: 사용 | G1: 빼기 | H1: 고쳐서 사용
A2: 브론즈 | B2: 1 | C2: 40 | D2: =COUNTIFS('전체 지문'!$B:$B,$A2,'전체 지문'!$C:$C,$B2) -> 10 | E2: =IFERROR(AVERAGEIFS('전체 지문'!$K:$K,'전체 지문'!$B:$B,$A2,'전체 지문'!$C:$C,$B2),0) -> 40.7 | F2: =COUNTIFS('전체 지문'!$B:$B,$A2,'전체 지문'!$C:$C,$B2,'전체 지문'!$P:$P,"사용") -> 10 | G2: =COUNTIFS('전체 지문'!$B:$B,$A2,'전체 지문'!$C:$C,$B2,'전체 지문'!$P:$P,"빼기") -> 0 | H2: =COUNTIFS('전체 지문'!$B:$B,$A2,'전체 지문'!$C:$C,$B2,'전체 지문'!$P:$P,"고쳐서 사용") -> 0
A3: 브론즈 | B3: 2 | C3: 50 | D3: =COUNTIFS('전체 지문'!$B:$B,$A3,'전체 지문'!$C:$C,$B3) -> 10 | E3: =IFERROR(AVERAGEIFS('전체 지문'!$K:$K,'전체 지문'!$B:$B,$A3,'전체 지문'!$C:$C,$B3),0) -> 34 | F3: =COUNTIFS('전체 지문'!$B:$B,$A3,'전체 지문'!$C:$C,$B3,'전체 지문'!$P:$P,"사용") -> 10 | G3: =COUNTIFS('전체 지문'!$B:$B,$A3,'전체 지문'!$C:$C,$B3,'전체 지문'!$P:$P,"빼기") -> 0 | H3: =COUNTIFS('전체 지문'!$B:$B,$A3,'전체 지문'!$C:$C,$B3,'전체 지문'!$P:$P,"고쳐서 사용") -> 0
A4: 브론즈 | B4: 3 | C4: 60 | D4: =COUNTIFS('전체 지문'!$B:$B,$A4,'전체 지문'!$C:$C,$B4) -> 10 | E4: =IFERROR(AVERAGEIFS('전체 지문'!$K:$K,'전체 지문'!$B:$B,$A4,'전체 지문'!$C:$C,$B4),0) -> 30.5 | F4: =COUNTIFS('전체 지문'!$B:$B,$A4,'전체 지문'!$C:$C,$B4,'전체 지문'!$P:$P,"사용") -> 10 | G4: =COUNTIFS('전체 지문'!$B:$B,$A4,'전체 지문'!$C:$C,$B4,'전체 지문'!$P:$P,"빼기") -> 0 | H4: =COUNTIFS('전체 지문'!$B:$B,$A4,'전체 지문'!$C:$C,$B4,'전체 지문'!$P:$P,"고쳐서 사용") -> 0
A5: 브론즈 | B5: 4 | C5: 70 | D5: =COUNTIFS('전체 지문'!$B:$B,$A5,'전체 지문'!$C:$C,$B5) -> 10 | E5: =IFERROR(AVERAGEIFS('전체 지문'!$K:$K,'전체 지문'!$B:$B,$A5,'전체 지문'!$C:$C,$B5),0) -> 24.8 | F5: =COUNTIFS('전체 지문'!$B:$B,$A5,'전체 지문'!$C:$C,$B5,'전체 지문'!$P:$P,"사용") -> 10 | G5: =COUNTIFS('전체 지문'!$B:$B,$A5,'전체 지문'!$C:$C,$B5,'전체 지문'!$P:$P,"빼기") -> 0 | H5: =COUNTIFS('전체 지문'!$B:$B,$A5,'전체 지문'!$C:$C,$B5,'전체 지문'!$P:$P,"고쳐서 사용") -> 0
A6: 브론즈 | B6: 5 | C6: 80 | D6: =COUNTIFS('전체 지문'!$B:$B,$A6,'전체 지문'!$C:$C,$B6) -> 10 | E6: =IFERROR(AVERAGEIFS('전체 지문'!$K:$K,'전체 지문'!$B:$B,$A6,'전체 지문'!$C:$C,$B6),0) -> 22.5 | F6: =COUNTIFS('전체 지문'!$B:$B,$A6,'전체 지문'!$C:$C,$B6,'전체 지문'!$P:$P,"사용") -> 10 | G6: =COUNTIFS('전체 지문'!$B:$B,$A6,'전체 지문'!$C:$C,$B6,'전체 지문'!$P:$P,"빼기") -> 0 | H6: =COUNTIFS('전체 지문'!$B:$B,$A6,'전체 지문'!$C:$C,$B6,'전체 지문'!$P:$P,"고쳐서 사용") -> 0
A7: 실버 | B7: 1 | C7: 95 | D7: =COUNTIFS('전체 지문'!$B:$B,$A7,'전체 지문'!$C:$C,$B7) -> 30 | E7: =IFERROR(AVERAGEIFS('전체 지문'!$K:$K,'전체 지문'!$B:$B,$A7,'전체 지문'!$C:$C,$B7),0) -> 3.5333333 | F7: =COUNTIFS('전체 지문'!$B:$B,$A7,'전체 지문'!$C:$C,$B7,'전체 지문'!$P:$P,"사용") -> 30 | G7: =COUNTIFS('전체 지문'!$B:$B,$A7,'전체 지문'!$C:$C,$B7,'전체 지문'!$P:$P,"빼기") -> 0 | H7: =COUNTIFS('전체 지문'!$B:$B,$A7,'전체 지문'!$C:$C,$B7,'전체 지문'!$P:$P,"고쳐서 사용") -> 0
A8: 실버 | B8: 2 | C8: 106 | D8: =COUNTIFS('전체 지문'!$B:$B,$A8,'전체 지문'!$C:$C,$B8) -> 30 | E8: =IFERROR(AVERAGEIFS('전체 지문'!$K:$K,'전체 지문'!$B:$B,$A8,'전체 지문'!$C:$C,$B8),0) -> 4.5666667 | F8: =COUNTIFS('전체 지문'!$B:$B,$A8,'전체 지문'!$C:$C,$B8,'전체 지문'!$P:$P,"사용") -> 30 | G8: =COUNTIFS('전체 지문'!$B:$B,$A8,'전체 지문'!$C:$C,$B8,'전체 지문'!$P:$P,"빼기") -> 0 | H8: =COUNTIFS('전체 지문'!$B:$B,$A8,'전체 지문'!$C:$C,$B8,'전체 지문'!$P:$P,"고쳐서 사용") -> 0
A9: 실버 | B9: 3 | C9: 118 | D9: =COUNTIFS('전체 지문'!$B:$B,$A9,'전체 지문'!$C:$C,$B9) -> 30 | E9: =IFERROR(AVERAGEIFS('전체 지문'!$K:$K,'전체 지문'!$B:$B,$A9,'전체 지문'!$C:$C,$B9),0) -> 5.2 | F9: =COUNTIFS('전체 지문'!$B:$B,$A9,'전체 지문'!$C:$C,$B9,'전체 지문'!$P:$P,"사용") -> 30 | G9: =COUNTIFS('전체 지문'!$B:$B,$A9,'전체 지문'!$C:$C,$B9,'전체 지문'!$P:$P,"빼기") -> 0 | H9: =COUNTIFS('전체 지문'!$B:$B,$A9,'전체 지문'!$C:$C,$B9,'전체 지문'!$P:$P,"고쳐서 사용") -> 0
A10: 실버 | B10: 4 | C10: 129 | D10: =COUNTIFS('전체 지문'!$B:$B,$A10,'전체 지문'!$C:$C,$B10) -> 30 | E10: =IFERROR(AVERAGEIFS('전체 지문'!$K:$K,'전체 지문'!$B:$B,$A10,'전체 지문'!$C:$C,$B10),0) -> 5.6333333 | F10: =COUNTIFS('전체 지문'!$B:$B,$A10,'전체 지문'!$C:$C,$B10,'전체 지문'!$P:$P,"사용") -> 30 | G10: =COUNTIFS('전체 지문'!$B:$B,$A10,'전체 지문'!$C:$C,$B10,'전체 지문'!$P:$P,"빼기") -> 0 | H10: =COUNTIFS('전체 지문'!$B:$B,$A10,'전체 지문'!$C:$C,$B10,'전체 지문'!$P:$P,"고쳐서 사용") -> 0
A11: 실버 | B11: 5 | C11: 140 | D11: =COUNTIFS('전체 지문'!$B:$B,$A11,'전체 지문'!$C:$C,$B11) -> 30 | E11: =IFERROR(AVERAGEIFS('전체 지문'!$K:$K,'전체 지문'!$B:$B,$A11,'전체 지문'!$C:$C,$B11),0) -> 6.8333333 | F11: =COUNTIFS('전체 지문'!$B:$B,$A11,'전체 지문'!$C:$C,$B11,'전체 지문'!$P:$P,"사용") -> 30 | G11: =COUNTIFS('전체 지문'!$B:$B,$A11,'전체 지문'!$C:$C,$B11,'전체 지문'!$P:$P,"빼기") -> 0 | H11: =COUNTIFS('전체 지문'!$B:$B,$A11,'전체 지문'!$C:$C,$B11,'전체 지문'!$P:$P,"고쳐서 사용") -> 0
A12: 골드 | B12: 1 | C12: 155 | D12: =COUNTIFS('전체 지문'!$B:$B,$A12,'전체 지문'!$C:$C,$B12) -> 10 | E12: =IFERROR(AVERAGEIFS('전체 지문'!$K:$K,'전체 지문'!$B:$B,$A12,'전체 지문'!$C:$C,$B12),0) -> 19 | F12: =COUNTIFS('전체 지문'!$B:$B,$A12,'전체 지문'!$C:$C,$B12,'전체 지문'!$P:$P,"사용") -> 10 | G12: =COUNTIFS('전체 지문'!$B:$B,$A12,'전체 지문'!$C:$C,$B12,'전체 지문'!$P:$P,"빼기") -> 0 | H12: =COUNTIFS('전체 지문'!$B:$B,$A12,'전체 지문'!$C:$C,$B12,'전체 지문'!$P:$P,"고쳐서 사용") -> 0
A13: 골드 | B13: 2 | C13: 169 | D13: =COUNTIFS('전체 지문'!$B:$B,$A13,'전체 지문'!$C:$C,$B13) -> 10 | E13: =IFERROR(AVERAGEIFS('전체 지문'!$K:$K,'전체 지문'!$B:$B,$A13,'전체 지문'!$C:$C,$B13),0) -> 22.2 | F13: =COUNTIFS('전체 지문'!$B:$B,$A13,'전체 지문'!$C:$C,$B13,'전체 지문'!$P:$P,"사용") -> 10 | G13: =COUNTIFS('전체 지문'!$B:$B,$A13,'전체 지문'!$C:$C,$B13,'전체 지문'!$P:$P,"빼기") -> 0 | H13: =COUNTIFS('전체 지문'!$B:$B,$A13,'전체 지문'!$C:$C,$B13,'전체 지문'!$P:$P,"고쳐서 사용") -> 0
... A31: 레전드 | B31: 5 | C31: 400 | D31: =COUNTIFS('전체 지문'!$B:$B,$A31,'전체 지문'!$C:$C,$B31) -> 6 | E31: =IFERROR(AVERAGEIFS('전체 지문'!$K:$K,'전체 지문'!$B:$B,$A31,'전체 지문'!$C:$C,$B31),0) -> 113.83333 | F31: =COUNTIFS('전체 지문'!$B:$B,$A31,'전체 지문'!$C:$C,$B31,'전체 지문'!$P:$P,"사용") -> 6 | G31: =COUNTIFS('전체 지문'!$B:$B,$A31,'전체 지문'!$C:$C,$B31,'전체 지문'!$P:$P,"빼기") -> 0 | H31: =COUNTIFS('전체 지문'!$B:$B,$A31,'전체 지문'!$C:$C,$B31,'전체 지문'!$P:$P,"고쳐서 사용") -> 0
A32: 합계 | D32: =SUM(D2:D31) -> 369 | E32: =IFERROR(AVERAGE(E2:E31),0) -> 40.403528 | F32: =SUM(F2:F31) -> 369 | G32: =SUM(G2:G31) -> 0 | H32: =SUM(H2:H31) -> 0

Sheet 전체 지문
A1: ID | B1: 티어 | C1: 단계 | D1: 목표 타수 | E1: 정확도(%) | F1: 글 종류 | G1: 제목 | H1: 지문 | I1: 글자 수 | J1: 타수 | K1: 예상 시간(초) | L1: 단원 | M1: 쪽 | N1: 고친 점 | O1: 원문 일치율 | P1: 사용 여부 | Q1: 선생님 메모
A2: ko-bronze-1-01 | B2: 브론즈 | C2: 1 | D2: 40 | E2: 85 | F2: 자리 연습 | H2: 아이 오이 나라 머리 허리 | I2: 14 | J2: 24 | K2: 36 | P2: 사용
A3: ko-bronze-1-02 | B3: 브론즈 | C3: 1 | D3: 40 | E3: 85 | F3: 자리 연습 | H3: 하나 오리 마리 미나리 아리랑 | I3: 16 | J3: 29 | K3: 44 | P3: 사용
A4: ko-bronze-1-03 | B4: 브론즈 | C4: 1 | D4: 40 | E4: 85 | F4: 자리 연습 | H4: 호랑이 호미 엄마 인어 노인 | I4: 15 | J4: 30 | K4: 45 | P4: 사용
A5: ko-bronze-1-04 | B5: 브론즈 | C5: 1 | D5: 40 | E5: 85 | F5: 자리 연습 | H5: 나이 놀이 할머니 어린이 알림 | I5: 16 | J5: 33 | K5: 50 | P5: 사용
A6: ko-bronze-1-05 | B6: 브론즈 | C6: 1 | D6: 40 | E6: 85 | F6: 자리 연습 | H6: 말 날 일 알 얼마 어림 | I6: 13 | J6: 27 | K6: 40 | P6: 사용
A7: ko-bronze-1-06 | B7: 브론즈 | C7: 1 | D7: 40 | E7: 85 | F7: 자리 연습 | H7: 화로 외로이 왼 놀라 와 | I7: 13 | J7: 28 | K7: 42 | P7: 사용
A8: ko-bronze-1-07 | B8: 브론즈 | C8: 1 | D8: 40 | E8: 85 | F8: 자리 연습 | H8: 노란 오리 날아 오나 | I8: 11 | J8: 21 | K8: 32 | P8: 사용
A9: ko-bronze-1-08 | B9: 브론즈 | C9: 1 | D9: 40 | E9: 85 | F9: 자리 연습 | H9: 엄마 아이 놀이 할 일 | I9: 12 | J9: 24 | K9: 36 | P9: 사용
A10: ko-bronze-1-09 | B10: 브론즈 | C10: 1 | D10: 40 | E10: 85 | F10: 자리 연습 | H10: 이리 와 하나 마리 놀이 | I10: 13 | J10: 24 | K10: 36 | P10: 사용
A11: ko-bronze-1-10 | B11: 브론즈 | C11: 1 | D11: 40 | E11: 85 | F11: 자리 연습 | H11: 어머니 할머니 언니 아나 몰라 | I11: 16 | J11: 31 | K11: 46 | P11: 사용
A12: ko-bronze-2-01 | B12: 브론즈 | C12: 2 | D12: 50 | E12: 85 | F12: 자리 연습 | H12: 바다 지도 고기 사자 개미 | I12: 14 | J12: 24 | K12: 29 | P12: 사용
A13: ko-bronze-2-02 | B13: 브론즈 | C13: 2 | D13: 50 | E13: 85 | F13: 자리 연습 | H13: 가방 새 배 게 소리 가지 | I13: 14 | J13: 24 | K13: 29 | P13: 사용
... A51: ko-bronze-5-10 | B51: 브론즈 | C51: 5 | D51: 80 | E51: 85 | F51: 자리 연습 | H51: 괜찮아 천천히 정확하게 | I51: 12 | J51: 31 | K51: 23 | P51: 사용
A52: ko-silver-1-01 | B52: 실버 | C52: 1 | D52: 95 | E52: 88 | F52: 낱말 | H52: 버저 | I52: 2 | J52: 4 | K52: 3 | L52: Ⅴ. 디지털 문화 | M52: 205 | O52: 1 | P52: 사용
A53: ko-silver-1-02 | B53: 실버 | C53: 1 | D53: 95 | E53: 88 | F53: 낱말 | H53: 트리 | I53: 2 | J53: 4 | K53: 3 | L53: Ⅴ. 디지털 문화 | M53: 198 | O53: 1 | P53: 사용
A54: ko-silver-1-03 | B54: 실버 | C54: 1 | D54: 95 | E54: 88 | F54: 낱말 | H54: 추세 | I54: 2 | J54: 4 | K54: 3 | L54: Ⅱ. 데이터 | M54: 65 | O54: 1 | P54: 사용
A55: ko-silver-1-04 | B55: 실버 | C55: 1 | D55: 95 | E55: 88 | F55: 낱말 | H55: 쿠키 | I55: 2 | J55: 4 | K55: 3 | L55: Ⅴ. 디지털 문화 | M55: 210 | O55: 1 | P55: 사용
A56: ko-silver-1-05 | B56: 실버 | C56: 1 | D56: 95 | E56: 88 | F56: 낱말 | H56: 부팅 | I56: 2 | J56: 5 | K56: 3 | L56: Ⅰ. 컴퓨팅 시스템 | M56: 16 | O56: 1 | P56: 사용
A57: ko-silver-1-06 | B57: 실버 | C57: 1 | D57: 95 | E57: 88 | F57: 낱말 | H57: 센서 | I57: 2 | J57: 5 | K57: 3 | L57: Ⅴ. 디지털 문화 | M57: 190 | O57: 1 | P57: 사용
A58: ko-silver-1-07 | B58: 실버 | C58: 1 | D58: 95 | E58: 88 | F58: 낱말 | H58: 벡터 | I58: 2 | J58: 5 | K58: 3 | L58: Ⅱ. 데이터 | M58: 47 | O58: 1 | P58: 사용
A59: ko-silver-1-08 | B59: 실버 | C59: 1 | D59: 95 | E59: 88 | F59: 낱말 | H59: 파형 | I59: 2 | J59: 5 | K59: 3 | L59: Ⅱ. 데이터 | M59: 48 | O59: 1 | P59: 사용
A60: ko-silver-1-09 | B60: 실버 | C60: 1 | D60: 95 | E60: 88 | F60: 낱말 | H60: 변수 | I60: 2 | J60: 5 | K60: 3 | L60: Ⅲ. 알고리즘과 프로그래밍 | M60: 102 | O60: 1 | P60: 사용
A61: ko-silver-1-10 | B61: 실버 | C61: 1 | D61: 95 | E61: 88 | F61: 낱말 | H61: 함수 | I61: 2 | J61: 5 | K61: 3 | L61: Ⅲ. 알고리즘과 프로그래밍 | M61: 78 | O61: 1 | P61: 사용
A62: ko-silver-1-11 | B62: 실버 | C62: 1 | D62: 95 | E62: 88 | F62: 낱말 | H62: 추론 | I62: 2 | J62: 5 | K62: 3 | L62: Ⅳ. 인공지능 | M62: 147 | O62: 1 | P62: 사용
A63: ko-silver-1-12 | B63: 실버 | C63: 1 | D63: 95 | E63: 88 | F63: 낱말 | H63: 분류 | I63: 2 | J63: 5 | K63: 3 | L63: Ⅴ. 디지털 문화 | M63: 214 | O63: 1 | P63: 사용
... A204: ko-gold-1-03 | B204: 골드 | C204: 1 | D204: 155 | E204: 90 | F204: 문장 | H204: 미래에는 어떤 입력 장치들이 사용될까? | I204: 21 | J204: 46 | K204: 18 | L204: Ⅰ. 컴퓨팅 시스템 | M204: 22 | O204: 1 | P204: 사용
A205: ko-gold-1-04 | B205: 골드 | C205: 1 | D205: 155 | E205: 90 | F205: 문장 | H205: 이진수는 0과 1만을 사용하는 수 체계이다. | I205: 24 | J205: 47 | K205: 18 | L205: Ⅱ. 데이터 | M205: 46 | N205: 용어 풀이를 문장으로 바꿈 | O205: 1 | P205: 사용
A206: ko-gold-1-05 | B206: 골드 | C206: 1 | D206: 155 | E206: 90 | F206: 문장 | H206: 이미 만들어 놓은 함수는 재사용이 가능하다. | I206: 24 | J206: 50 | K206: 19 | L206: Ⅲ. 알고리즘과 프로그래밍 | M206: 121 | O206: 1 | P206: 사용
A207: ko-gold-1-06 | B207: 골드 | C207: 1 | D207: 155 | E207: 90 | F207: 문장 | H207: 문제는 해결해야 하는 일이나 과제를 말한다. | I207: 24 | J207: 51 | K207: 20 | L207: Ⅲ. 알고리즘과 프로그래밍 | M207: 81 | O207: 1 | P207: 사용
A208: ko-gold-1-07 | B208: 골드 | C208: 1 | D208: 155 | E208: 90 | F208: 문장 | H208: 연산자는 연산을 하기 위한 기호를 말한다. | I208: 23 | J208: 51 | K208: 20 | L208: Ⅲ. 알고리즘과 프로그래밍 | M208: 108 | N208: 용어 풀이를 문장으로 바꿈 | O208: 1 | P208: 사용
A209: ko-gold-1-08 | B209: 골드 | C209: 1 | D209: 155 | E209: 90 | F209: 문장 | H209: 프로그램에서 중복되는 코드를 제거할 수 있다. | I209: 25 | J209: 52 | K209: 20 | L209: Ⅲ. 알고리즘과 프로그래밍 | M209: 118 | O209: 1 | P209: 사용
A210: ko-gold-1-09 | B210: 골드 | C210: 1 | D210: 155 | E210: 90 | F210: 문장 | H210: 함수는 여러 가지 형태로 다양하게 응용할 수 있다. | I210: 28 | J210: 56 | K210: 22 | L210: Ⅲ. 알고리즘과 프로그래밍 | M210: 122 | O210: 1 | P210: 사용
A211: ko-gold-1-10 | B211: 골드 | C211: 1 | D211: 155 | E211: 90 | F211: 문장 | H211: 엔트리봇이 달리고 점프하는 프로그램을 작성해 보자. | I211: 28 | J211: 59 | K211: 23 | L211: Ⅲ. 알고리즘과 프로그래밍 | M211: 115 | O211: 1 | P211: 사용
A212: ko-gold-2-01 | B212: 골드 | C212: 2 | D212: 169 | E212: 90 | F212: 문장 | H212: 컴퓨팅 시스템은 하드웨어와 소프트웨어로 구성된다. | I212: 27 | J212: 59 | K212: 21 | L212: Ⅰ. 컴퓨팅 시스템 | M212: 12 | O212: 1 | P212: 사용
A213: ko-gold-2-02 | B213: 골드 | C213: 2 | D213: 169 | E213: 90 | F213: 문장 | H213: 알고리즘은 특정 문제를 해결하는 절차나 방법이다. | I213: 27 | J213: 60 | K213: 21 | L213: Ⅲ. 알고리즘과 프로그래밍 | M213: 86 | O213: 1 | P213: 사용
A214: ko-gold-2-03 | B214: 골드 | C214: 2 | D214: 169 | E214: 90 | F214: 문장 | H214: 다이어그램의 유형에는 계층형과 그래프형 등이 있다. | I214: 28 | J214: 60 | K214: 21 | L214: Ⅱ. 데이터 | M214: 61 | O214: 1 | P214: 사용
A215: ko-gold-2-04 | B215: 골드 | C215: 2 | D215: 169 | E215: 90 | F215: 문장 | H215: 프레임은 동영상을 구성하는 하나의 장면을 말한다. | I215: 27 | J215: 62 | K215: 22 | L215: Ⅱ. 데이터 | M215: 48 | N215: 용어 풀이를 문장으로 바꿈 | O215: 1 | P215: 사용
A216: ko-gold-2-05 | B216: 골드 | C216: 2 | D216: 169 | E216: 90 | F216: 문장 | H216: 개인 정보란 살아 있는 개인에 관한 정보를 말한다. | I216: 28 | J216: 62 | K216: 22 | L216: Ⅴ. 디지털 문화 | M216: 210 | O216: 1 | P216: 사용
A217: ko-gold-2-06 | B217: 골드 | C217: 2 | D217: 169 | E217: 90 | F217: 문장 | H217: 주어진 문제를 해결하는 알고리즘은 여러 가지일 수 있다. | I217: 31 | J217: 64 | K217: 23 | L217: Ⅲ. 알고리즘과 프로그래밍 | M217: 88 | O217: 1 | P217: 사용
...
